<?xml version="1.0" ?>
<robot name="ads-mt" xmlns:xacro="http://www.ros.org/wiki/xacro">

    <xacro:include filename="$(find labsim)/labsim/urdf/adsmt-wheeled.gazebo" />

    <link name = "base_footprint">
        <!-- Nth in here -->
    </link>
    <joint name = "body_link_joint" type='fixed'>
        <origin xyz="0 0.00 0.1565" rpy="0 0 0"/>
        <parent link="base_footprint"/>
        <child link="body"/>
    </joint>

    <material name="yellow">
        <color rgba="1 0.5 0 1"/>
    </material>

    <material name="black">
        <color rgba="0.02 0.02 0.02 1"/>
    </material>

    <material name="grey">
        <color rgba="0.06 0.06 0.06 1"/>
    </material>

    <!-- Base Link -->
    <link name="body">
        <visual>
            <geometry>
                <mesh filename="$(find labsim)/labsim/urdf/designs/body.stl" scale=" 0.001 0.001 0.001"/>
            </geometry>
            <material name='grey'/>
        </visual>
        <collision>
            <density>1060.0</density>
           <origin xyz="0 0 0"/>
           <geometry>
              <mesh filename="$(find labsim)/labsim/urdf/designs/body.stl" scale=" 0.001 0.001 0.001"/>
           </geometry>
        </collision>
        <inertial>
            <mass value="0.29"/>
            <origin xyz="0 0 0"/>
            <inertia ixx="0.000193" ixy="0.0" ixz="0.0" iyy="0.000694" iyz="0.0" izz="0.000529"/>
        </inertial>
    </link>

    <!-- Leg 1 -->
    <!-- Joints and Links -->
    <joint name="joint_1" type="revolute">
        <parent link="body"/>
        <child link="joint_1_link"/>
        <origin xyz="-0.0255 -0.060 0.0" rpy="0 0 -1.5708"/>
        <axis xyz="0 0 1"/>
        <limit lower="-3.1415" upper="3.1415" effort="50" velocity="2.0"/>
    </joint>
    <link name="joint_1_link">
        <inertial>
            <mass value="0.018"/>
            <origin xyz="0 0 0"/>
            <inertia ixx="0.000008268" ixy="0.0" ixz="0.0" iyy="0.000008268" iyz="0.0" izz="0.000003468"/>
        </inertial>
        <visual>
            <geometry>
                <mesh filename="$(find labsim)/labsim/urdf/designs/double_u.stl" scale=" 0.001 0.001 0.001"/>
            </geometry>
            <material name='yellow'/>
        </visual>
        <collision>
            <geometry>
                <mesh filename="$(find labsim)/labsim/urdf/designs/double_u.stl" scale=" 0.001 0.001 0.001"/>

            </geometry>
        </collision>
    </link>


    <!-- Thigh 1 -->
    <joint name="joint_1_1" type="revolute">
        <parent link="joint_1_link"/>
        <child link="joint_1_thigh"/>
        <origin xyz="-0.0 -0.046 -0.0" rpy="-1.5708 0 0"/>
        <axis xyz="1 0 0"/>
        <limit lower="-3.1415" upper="3.1415" effort="50" velocity="2.0"/>
    </joint>
    <link name="joint_1_thigh">
        <inertial>
            <mass value="0.06"/>
            <origin xyz="0 0 0"/>
            <inertia ixx="0.0000193" ixy="0.0" ixz="0.0" iyy="0.0000202" iyz="0.0" izz="0.00000331"/>
        </inertial>
        <visual>

            <geometry>
                <mesh filename="$(find labsim)/labsim/urdf/designs/thigh.stl" scale=" 0.001 0.001 0.001"/>
            </geometry>
            <material name='black'></material>
        </visual>
        <collision>
            <origin xyz="0 0 0"/>
            <geometry>
                <mesh filename="$(find labsim)/labsim/urdf/designs/thigh.stl" scale=" 0.001 0.001 0.001"/>

            </geometry>
        </collision>
    </link>

    <!-- Shin 1 -->
    <joint name="joint_1_1_1" type="revolute">
        <parent link="joint_1_thigh"/>
        <child link="joint_1_shin"/>
        <origin xyz="-0.0 0.065 0.0" rpy="3.1415 0 0"/>
        <axis xyz="1 0 0"/>
        <limit lower="-3.1415" upper="3.1415" effort="50" velocity="2.0"/>
    </joint>
    <link name="joint_1_shin">
        <inertial>
            <mass value="0.06"/>
            <origin xyz="0 0 0"/>
            <inertia ixx="0.00003064" ixy="0.0" ixz="0" iyy="0.00003232" iyz="0.0" izz="0.0000041"/>

        </inertial>
        <visual>
            <geometry>
                <mesh filename="$(find labsim)/labsim/urdf/designs/shin.stl" scale=" 0.001 0.001 0.001"/>
            </geometry>
            <material name='yellow'></material>
        </visual>
        <collision>
            <geometry>
                <mesh filename="$(find labsim)/labsim/urdf/designs/shin.stl" scale=" 0.001 0.001 0.001"/>
            </geometry>
        </collision>
    </link>

    <!-- Wheel 1 -->
    <joint name="wheel_1" type="continuous">
        <parent link="joint_1_shin"/>
        <child link="joint_1_wheel"/>
        <origin xyz="0.018 -0.065 0.0" rpy="1.5708 0 1.5708"/>
        <axis xyz="0 0 1"/>
        <dynamics damping="0.01" friction='1.0' />
        <limit lower="-3.1415" upper="3.1415" effort="150" velocity="50.0"/>
    </joint>
    <link name="joint_1_wheel">
        <inertial>
            <mass value="0.06"/>
            <origin xyz="0 0 0"/>
            <inertia ixx="0.000135" ixy="0.0" ixz="0" iyy="0.000135" iyz="0.0" izz="0.000265"/>

        </inertial>
        <visual>
            <geometry>
                <cylinder radius="0.023" length = "0.0055"/>
            </geometry>
            <material name='black'></material>
        </visual>
        <collision>
            <geometry>
                <cylinder radius="0.023" length = "0.0055"/>
            </geometry>
        </collision>
    </link>

    <!-- /Leg 1 -->

    <!-- Leg 2 -->
    <joint name="joint_2" type="revolute">
        <parent link="body"/>
        <child link="joint_2_link"/>
        <origin xyz="-0.0255 0.06 0.0" rpy="0 0 -1.5708"/>
        <axis xyz="0 0 1"/>
        <limit lower="-3.1415" upper="3.1415" effort="50" velocity="2.0"/>
    </joint>
    <link name="joint_2_link">
        <inertial>
            <mass value="0.018"/>
            <origin xyz="0 0 0"/>
            <inertia ixx="0.000133" ixy="0.0" ixz="0.0" iyy="0.000133" iyz="0.0" izz="0.0000558"/>

        </inertial>
        <visual>
            <geometry>
                <mesh filename="$(find labsim)/labsim/urdf/designs/double_u.stl" scale=" 0.001 0.001 0.001"/>
            </geometry>
            <material name='yellow'/>
        </visual>

        <collision>
            <geometry>
                <mesh filename="$(find labsim)/labsim/urdf/designs/double_u.stl" scale=" 0.001 0.001 0.001"/>
            </geometry>
        </collision>

    </link>

    <!-- Thigh 2 -->
    <joint name="joint_2_1" type="revolute">
        <parent link="joint_2_link"/>
        <child link="joint_2_thigh"/>
        <origin xyz="-0.0 -0.046 0.0" rpy="-1.5708 0 0"/>
        <axis xyz="1 0 0"/>
        <limit lower="-3.1415" upper="3.1415" effort="50" velocity="2.0"/>
    </joint>
    <link name="joint_2_thigh">
        <inertial>
            <mass value="0.06"/>
            <origin xyz="0 0 0"/>
            <inertia ixx="0.0000193" ixy="0.0" ixz="0.0" iyy="0.0000202" iyz="0.0" izz="0.00000331"/>
        </inertial>
        <visual>
            <geometry>
                <mesh filename="$(find labsim)/labsim/urdf/designs/thigh.stl" scale=" 0.001 0.001 0.001"/>
            </geometry>
            <material name='black'></material>
        </visual>
        <collision>
            <geometry>
                <mesh filename="$(find labsim)/labsim/urdf/designs/thigh.stl" scale=" 0.001 0.001 0.001"/>
            </geometry>
        </collision>
    </link>


    <!-- Shin 2 -->
    <joint name="joint_2_1_1" type="revolute">
        <parent link="joint_2_thigh"/>
        <child link="joint_2_shin"/>
        <origin xyz="-0.0 0.065 0.0" rpy="3.1415 0 0"/>
        <axis xyz="1 0 0"/>
        <limit lower="-3.1415" upper="3.1415" effort="50" velocity="2.0"/>
    </joint>
    <link name="joint_2_shin">
        <inertial>
            <mass value="0.06"/>
            <origin xyz="0 0 0"/>
            <inertia ixx="0.00003064" ixy="0.0" ixz="0" iyy="0.00003232" iyz="0.0" izz="0.0000041"/>

        </inertial>
        <visual>
            <geometry>
                <mesh filename="$(find labsim)/labsim/urdf/designs/shin.stl" scale=" 0.001 0.001 0.001"/>
            </geometry>
            <material name='yellow'></material>
        </visual>
        <collision>
            <geometry>
                <mesh filename="$(find labsim)/labsim/urdf/designs/shin.stl" scale=" 0.001 0.001 0.001"/>
            </geometry>
        </collision>
    </link>
    <joint name="wheel_2" type="continuous">
        <parent link="joint_2_shin"/>
        <child link="joint_2_wheel"/>
        <origin xyz="-0.018 -0.065 0.0" rpy="1.5708 0 1.5708"/>
        <dynamics damping="0.01" friction='1.0' />
        <axis xyz="0 0 1"/>
        <limit lower="-3.1415" upper="3.1415" effort="150" velocity="50.0"/>
    </joint>
    <!-- Wheel 2 -->
    <link name="joint_2_wheel">
        <inertial>
            <mass value="0.06"/>
            <origin xyz="0 0 0"/>
            <inertia ixx="0.000135" ixy="0.0" ixz="0" iyy="0.000135" iyz="0.0" izz="0.000265"/>

        </inertial>
        <visual>
            <geometry>
                <cylinder radius="0.023" length = "0.0055"/>
            </geometry>
            <material name='black'></material>
        </visual>
        <collision>
            <geometry>
                <cylinder radius="0.023" length = "0.0055"/>
            </geometry>
        </collision>
    </link>


    <!-- /Leg 2-->

    <!-- Leg 3 -->
    <joint name="joint_3" type="revolute">
        <parent link="body"/>
        <child link="joint_3_link"/>
        <origin xyz="0.025 -0.060 -0.0" rpy="0 0 1.5708"/>
        <axis xyz="0 0 1"/>
        <limit lower="-3.1415" upper="3.1415" effort="50" velocity="2.0"/>
    </joint>
    <link name="joint_3_link">
        <inertial>
            <mass value="0.018"/>
            <origin xyz="0 0 0"/>
            <inertia ixx="0.000133" ixy="0.0" ixz="0.0" iyy="0.000133" iyz="0.0" izz="0.0000558"/>
        </inertial>
        <visual>
            <geometry>
                <mesh filename="$(find labsim)/labsim/urdf/designs/double_u.stl" scale=" 0.001 0.001 0.001"/>
            </geometry>
            <material name='yellow'></material>
        </visual>
        <collision>
            <geometry>
                <mesh filename="$(find labsim)/labsim/urdf/designs/double_u.stl" scale=" 0.001 0.001 0.001"/>
            </geometry>
        </collision>

    </link>

    <!-- Thigh 3 -->
    <joint name="joint_3_1" type="revolute">
        <parent link="joint_3_link"/>
        <child link="joint_3_thigh"/>
        <origin xyz="-0.00 -0.046 -0.00" rpy="-1.5708 0 0"/>
        <axis xyz="1 0 0"/>
        <limit lower="-3.1415" upper="3.1415" effort="50" velocity="2.0"/>
    </joint>
    <link name="joint_3_thigh">
        <inertial>
            <mass value="0.06"/>
            <origin xyz="0 0 0"/>
            <inertia ixx="0.0000193" ixy="0.0" ixz="0.0" iyy="0.0000202" iyz="0.0" izz="0.00000331"/>
        </inertial>
        <visual>
            <geometry>
                <mesh filename="$(find labsim)/labsim/urdf/designs/thigh.stl" scale=" 0.001 0.001 0.001"/>
            </geometry>
            <material name='black'></material>
        </visual>
        <collision>
            <geometry>
                <mesh filename="$(find labsim)/labsim/urdf/designs/thigh.stl" scale=" 0.001 0.001 0.001"/>
            </geometry>
        </collision>
    </link>


    <!-- Shin 3 -->
    <joint name="joint_3_1_1" type="revolute">
        <parent link="joint_3_thigh"/>
        <child link="joint_3_shin"/>
        <origin xyz="-0.0 0.065 -0.00" rpy="3.1415 0 0"/>
        <axis xyz="1 0 0"/>
        <limit lower="-3.1415" upper="3.1415" effort="50" velocity="2.0"/>
    </joint>
    <link name="joint_3_shin">
        <inertial>
            <mass value="0.06"/>
            <origin xyz="0 0 0"/>
            <inertia ixx="0.00003064" ixy="0.0" ixz="0" iyy="0.00003232" iyz="0.0" izz="0.0000041"/>
        </inertial>
        <visual>
            <geometry>
                <mesh filename="$(find labsim)/labsim/urdf/designs/shin.stl" scale=" 0.001 0.001 0.001"/>
            </geometry>
            <material name='yellow'></material>
        </visual>
        <collision>
            <geometry>
                <mesh filename="$(find labsim)/labsim/urdf/designs/shin.stl" scale=" 0.001 0.001 0.001"/>
            </geometry>
        </collision>
    </link>

    <!-- Wheel 3 -->
    <joint name="wheel_3" type="continuous">
        <parent link="joint_3_shin"/>
        <dynamics damping="0.01" friction='1.0' />
        <child link="joint_3_wheel"/>
        <origin xyz="-0.018 -0.065 0.0" rpy="1.5708 0 1.5708"/>
        <axis xyz="0 0 1"/>
        <limit lower="-3.1415" upper="3.1415" effort="150" velocity="50.0"/>
    </joint>
    <link name="joint_3_wheel">
        <inertial>
            <mass value="0.06"/>
            <origin xyz="0 0 0"/>
            <inertia ixx="0.000135" ixy="0.0" ixz="0" iyy="0.000135" iyz="0.0" izz="0.000265"/>

        </inertial>
        <visual>
            <geometry>
                <cylinder radius="0.023" length = "0.0055"/>
            </geometry>
            <material name='black'></material>
        </visual>
        <collision>
            <geometry>
                <cylinder radius="0.023" length = "0.0055"/>
            </geometry>
        </collision>
    </link>


    <!-- /Leg 3-->

    <!-- Leg 4 -->
    <joint name="joint_4" type="revolute">
        <parent link="body"/>
        <child link="joint_4_link"/>
        <origin xyz="0.0250 0.06 0.0" rpy="0 0 1.5708"/>
        <axis xyz="0 0 1"/>
        <limit lower="-3.1415" upper="3.1415" effort="50" velocity="2.0"/>
    </joint>
    <link name="joint_4_link">
        <inertial>
            <mass value="0.018"/>
            <origin xyz="0 0 0"/>
            <inertia ixx="0.000133" ixy="0.0" ixz="0.0" iyy="0.000133" iyz="0.0" izz="0.0000558"/>
        </inertial>
        <visual>
            <geometry>
                <mesh filename="$(find labsim)/labsim/urdf/designs/double_u.stl" scale=" 0.001 0.001 0.001"/>
            </geometry>
            <material name='yellow'></material>
        </visual>
        <collision>
            <geometry>
                <mesh filename="$(find labsim)/labsim/urdf/designs/double_u.stl" scale=" 0.001 0.001 0.001"/>
            </geometry>
        </collision>
    </link>

    <!-- Thigh 4 -->
    <joint name="joint_4_1" type="revolute">
        <parent link="joint_4_link"/>
        <child link="joint_4_thigh"/>
        <origin xyz="-0.0 -0.046 0.0" rpy="-1.5708 0 0"/>
        <axis xyz="1 0 0"/>
        <limit lower="-3.1415" upper="3.1415" effort="50" velocity="2.0"/>
    </joint>
    <link name="joint_4_thigh">
        <inertial>
            <mass value="0.06"/>
            <origin xyz="0 0 0"/>
            <inertia ixx="0.0000193" ixy="0.0" ixz="0.0" iyy="0.0000202" iyz="0.0" izz="0.00000331"/>
        </inertial>
        <visual>
            <geometry>
                <mesh filename="$(find labsim)/labsim/urdf/designs/thigh.stl" scale=" 0.001 0.001 0.001"/>
            </geometry>
            <material name='black'></material>
        </visual>
        <collision>
            <geometry>
                <mesh filename="$(find labsim)/labsim/urdf/designs/thigh.stl" scale=" 0.001 0.001 0.001"/>
            </geometry>
        </collision>
    </link>


    <!-- Shin 4 -->
    <joint name="joint_4_1_1" type="revolute">
        <parent link="joint_4_thigh"/>
        <child link="joint_4_shin"/>
        <origin xyz="-0.0 0.065 0.0" rpy="3.1415 0 0"/>
        <axis xyz="1 0 0"/>
        <limit lower="-3.1415" upper="3.1415" effort="50" velocity="2.0"/>
    </joint>
    <link name="joint_4_shin">
        <inertial>
            <mass value="0.06"/>
            <origin xyz="0 0 0"/>
            <inertia ixx="0.00003064" ixy="0.0" ixz="0" iyy="0.00003232" iyz="0.0" izz="0.0000041"/>
        </inertial>
        <visual>
            <geometry>
                <mesh filename="$(find labsim)/labsim/urdf/designs/shin.stl" scale=" 0.001 0.001 0.001"/>
            </geometry>
            <material name='yellow'></material>
        </visual>
        <collision>
            <geometry>
                <mesh filename="$(find labsim)/labsim/urdf/designs/shin.stl" scale=" 0.001 0.001 0.001"/>
            </geometry>
        </collision>
    </link>

    <!-- Wheel 4 -->
    <joint name="wheel_4" type="continuous">
        <parent link="joint_4_shin"/>
        <dynamics damping="0.01" friction='1.0' />
        <child link="joint_4_wheel"/>
        <origin xyz="0.018 -0.065 0.0" rpy="1.5708 0 1.5708"/>
        <axis xyz="0 0 1"/>
        <limit lower="-3.1415" upper="3.1415" effort="150" velocity="50.0"/>
    </joint>
    <link name="joint_4_wheel">
        <inertial>
            <mass value="0.06"/>
            <origin xyz="0 0 0"/>
            <inertia ixx="0.000135" ixy="0.0" ixz="0" iyy="0.000135" iyz="0.0" izz="0.000265"/>

        </inertial>
        <visual>
            <geometry>
                <cylinder radius="0.023" length = "0.0055"/>
            </geometry>
            <material name='black'></material>
        </visual>
        <collision>
            <geometry>
                <cylinder radius="0.023" length = "0.0055"/>
            </geometry>
        </collision>
    </link>
    <!-- /Leg 4 -->
</robot>
